[2025-08-27T17:20:48.669+0000] {local_task_job_runner.py:123} INFO - ::group::Pre task execution logs
[2025-08-27T17:20:48.672+0000] {taskinstance.py:2612} INFO - Dependencies all met for dep_context=non-requeueable deps ti=<TaskInstance: ml_pipeline_simple.preprocess_train manual__2025-08-27T17:20:10+00:00 [queued]>
[2025-08-27T17:20:48.673+0000] {taskinstance.py:2612} INFO - Dependencies all met for dep_context=requeueable deps ti=<TaskInstance: ml_pipeline_simple.preprocess_train manual__2025-08-27T17:20:10+00:00 [queued]>
[2025-08-27T17:20:48.674+0000] {taskinstance.py:2865} INFO - Starting attempt 1 of 2
[2025-08-27T17:20:48.678+0000] {taskinstance.py:2888} INFO - Executing <Task(BashOperator): preprocess_train> on 2025-08-27 17:20:10+00:00
[2025-08-27T17:20:48.680+0000] {standard_task_runner.py:72} INFO - Started process 84 to run task
[2025-08-27T17:20:48.682+0000] {standard_task_runner.py:104} INFO - Running: ['airflow', 'tasks', 'run', 'ml_pipeline_simple', 'preprocess_train', 'manual__2025-08-27T17:20:10+00:00', '--job-id', '2', '--raw', '--subdir', 'DAGS_FOLDER/instructions.py', '--cfg-path', '/tmp/tmpk4__je3f']
[2025-08-27T17:20:48.683+0000] {standard_task_runner.py:105} INFO - Job 2: Subtask preprocess_train
[2025-08-27T17:20:48.697+0000] {task_command.py:467} INFO - Running <TaskInstance: ml_pipeline_simple.preprocess_train manual__2025-08-27T17:20:10+00:00 [running]> on host fd074bea2e82
[2025-08-27T17:20:48.718+0000] {taskinstance.py:3131} INFO - Exporting env vars: AIRFLOW_CTX_DAG_OWNER='airflow' AIRFLOW_CTX_DAG_ID='ml_pipeline_simple' AIRFLOW_CTX_TASK_ID='preprocess_train' AIRFLOW_CTX_EXECUTION_DATE='2025-08-27T17:20:10+00:00' AIRFLOW_CTX_TRY_NUMBER='1' AIRFLOW_CTX_DAG_RUN_ID='manual__2025-08-27T17:20:10+00:00'
[2025-08-27T17:20:48.719+0000] {taskinstance.py:731} INFO - ::endgroup::
[2025-08-27T17:20:48.732+0000] {subprocess.py:63} INFO - Tmp dir root location: /tmp
[2025-08-27T17:20:48.733+0000] {subprocess.py:75} INFO - Running command: ['/usr/bin/bash', '-c', 'python /opt/airflow/scripts/preprocess_training.py']
[2025-08-27T17:20:48.735+0000] {subprocess.py:86} INFO - Output:
[2025-08-27T17:20:49.426+0000] {subprocess.py:93} INFO - Traceback (most recent call last):
[2025-08-27T17:20:49.426+0000] {subprocess.py:93} INFO -   File "/home/airflow/.local/lib/python3.11/site-packages/pandas/core/indexes/base.py", line 3791, in get_loc
[2025-08-27T17:20:49.427+0000] {subprocess.py:93} INFO -     return self._engine.get_loc(casted_key)
[2025-08-27T17:20:49.427+0000] {subprocess.py:93} INFO -            ^^^^^^^^^^^^^^^^^^^^^^^^^^^^^^^^
[2025-08-27T17:20:49.429+0000] {subprocess.py:93} INFO -   File "index.pyx", line 152, in pandas._libs.index.IndexEngine.get_loc
[2025-08-27T17:20:49.430+0000] {subprocess.py:93} INFO -   File "index.pyx", line 181, in pandas._libs.index.IndexEngine.get_loc
[2025-08-27T17:20:49.430+0000] {subprocess.py:93} INFO -   File "pandas/_libs/hashtable_class_helper.pxi", line 7080, in pandas._libs.hashtable.PyObjectHashTable.get_item
[2025-08-27T17:20:49.430+0000] {subprocess.py:93} INFO -   File "pandas/_libs/hashtable_class_helper.pxi", line 7088, in pandas._libs.hashtable.PyObjectHashTable.get_item
[2025-08-27T17:20:49.430+0000] {subprocess.py:93} INFO - KeyError: 'W-L'
[2025-08-27T17:20:49.431+0000] {subprocess.py:93} INFO - 
[2025-08-27T17:20:49.431+0000] {subprocess.py:93} INFO - The above exception was the direct cause of the following exception:
[2025-08-27T17:20:49.431+0000] {subprocess.py:93} INFO - 
[2025-08-27T17:20:49.431+0000] {subprocess.py:93} INFO - Traceback (most recent call last):
[2025-08-27T17:20:49.431+0000] {subprocess.py:93} INFO -   File "/opt/airflow/scripts/preprocess_training.py", line 845, in <module>
[2025-08-27T17:20:49.431+0000] {subprocess.py:93} INFO -     mmkp[['Wins', 'Losses']] = mmkp['W-L'].str.split('-', expand=True).astype(int)
[2025-08-27T17:20:49.431+0000] {subprocess.py:93} INFO -                                ~~~~^^^^^^^
[2025-08-27T17:20:49.431+0000] {subprocess.py:93} INFO -   File "/home/airflow/.local/lib/python3.11/site-packages/pandas/core/frame.py", line 3893, in __getitem__
[2025-08-27T17:20:49.431+0000] {subprocess.py:93} INFO -     indexer = self.columns.get_loc(key)
[2025-08-27T17:20:49.431+0000] {subprocess.py:93} INFO -               ^^^^^^^^^^^^^^^^^^^^^^^^^
[2025-08-27T17:20:49.431+0000] {subprocess.py:93} INFO -   File "/home/airflow/.local/lib/python3.11/site-packages/pandas/core/indexes/base.py", line 3798, in get_loc
[2025-08-27T17:20:49.431+0000] {subprocess.py:93} INFO -     raise KeyError(key) from err
[2025-08-27T17:20:49.431+0000] {subprocess.py:93} INFO - KeyError: 'W-L'
[2025-08-27T17:20:49.455+0000] {subprocess.py:97} INFO - Command exited with return code 1
[2025-08-27T17:20:49.458+0000] {taskinstance.py:3310} ERROR - Task failed with exception
Traceback (most recent call last):
  File "/home/airflow/.local/lib/python3.11/site-packages/airflow/models/taskinstance.py", line 767, in _execute_task
    result = _execute_callable(context=context, **execute_callable_kwargs)
             ^^^^^^^^^^^^^^^^^^^^^^^^^^^^^^^^^^^^^^^^^^^^^^^^^^^^^^^^^^^^^
  File "/home/airflow/.local/lib/python3.11/site-packages/airflow/models/taskinstance.py", line 733, in _execute_callable
    return ExecutionCallableRunner(
           ^^^^^^^^^^^^^^^^^^^^^^^^
  File "/home/airflow/.local/lib/python3.11/site-packages/airflow/utils/operator_helpers.py", line 252, in run
    return self.func(*args, **kwargs)
           ^^^^^^^^^^^^^^^^^^^^^^^^^^
  File "/home/airflow/.local/lib/python3.11/site-packages/airflow/models/baseoperator.py", line 406, in wrapper
    return func(self, *args, **kwargs)
           ^^^^^^^^^^^^^^^^^^^^^^^^^^^
  File "/home/airflow/.local/lib/python3.11/site-packages/airflow/operators/bash.py", line 249, in execute
    raise AirflowException(
airflow.exceptions.AirflowException: Bash command failed. The command returned a non-zero exit code 1.
[2025-08-27T17:20:49.460+0000] {taskinstance.py:1225} INFO - Marking task as UP_FOR_RETRY. dag_id=ml_pipeline_simple, task_id=preprocess_train, run_id=manual__2025-08-27T17:20:10+00:00, execution_date=20250827T172010, start_date=20250827T172048, end_date=20250827T172049
[2025-08-27T17:20:49.467+0000] {taskinstance.py:340} INFO - ::group::Post task execution logs
[2025-08-27T17:20:49.467+0000] {standard_task_runner.py:124} ERROR - Failed to execute job 2 for task preprocess_train (Bash command failed. The command returned a non-zero exit code 1.; 84)
Traceback (most recent call last):
  File "/home/airflow/.local/lib/python3.11/site-packages/airflow/task/task_runner/standard_task_runner.py", line 117, in _start_by_fork
    ret = args.func(args, dag=self.dag)
          ^^^^^^^^^^^^^^^^^^^^^^^^^^^^^
  File "/home/airflow/.local/lib/python3.11/site-packages/airflow/cli/cli_config.py", line 49, in command
    return func(*args, **kwargs)
           ^^^^^^^^^^^^^^^^^^^^^
  File "/home/airflow/.local/lib/python3.11/site-packages/airflow/utils/cli.py", line 115, in wrapper
    return f(*args, **kwargs)
           ^^^^^^^^^^^^^^^^^^
  File "/home/airflow/.local/lib/python3.11/site-packages/airflow/cli/commands/task_command.py", line 483, in task_run
    task_return_code = _run_task_by_selected_method(args, _dag, ti)
                       ^^^^^^^^^^^^^^^^^^^^^^^^^^^^^^^^^^^^^^^^^^^^
  File "/home/airflow/.local/lib/python3.11/site-packages/airflow/cli/commands/task_command.py", line 256, in _run_task_by_selected_method
    return _run_raw_task(args, ti)
           ^^^^^^^^^^^^^^^^^^^^^^^
  File "/home/airflow/.local/lib/python3.11/site-packages/airflow/cli/commands/task_command.py", line 341, in _run_raw_task
    return ti._run_raw_task(
           ^^^^^^^^^^^^^^^^^
  File "/home/airflow/.local/lib/python3.11/site-packages/airflow/utils/session.py", line 97, in wrapper
    return func(*args, session=session, **kwargs)
           ^^^^^^^^^^^^^^^^^^^^^^^^^^^^^^^^^^^^^^
  File "/home/airflow/.local/lib/python3.11/site-packages/airflow/models/taskinstance.py", line 3004, in _run_raw_task
    return _run_raw_task(
           ^^^^^^^^^^^^^^
  File "/home/airflow/.local/lib/python3.11/site-packages/airflow/models/taskinstance.py", line 273, in _run_raw_task
    TaskInstance._execute_task_with_callbacks(
  File "/home/airflow/.local/lib/python3.11/site-packages/airflow/models/taskinstance.py", line 3158, in _execute_task_with_callbacks
    result = self._execute_task(context, task_orig)
             ^^^^^^^^^^^^^^^^^^^^^^^^^^^^^^^^^^^^^^
  File "/home/airflow/.local/lib/python3.11/site-packages/airflow/models/taskinstance.py", line 3182, in _execute_task
    return _execute_task(self, context, task_orig)
           ^^^^^^^^^^^^^^^^^^^^^^^^^^^^^^^^^^^^^^^
  File "/home/airflow/.local/lib/python3.11/site-packages/airflow/models/taskinstance.py", line 767, in _execute_task
    result = _execute_callable(context=context, **execute_callable_kwargs)
             ^^^^^^^^^^^^^^^^^^^^^^^^^^^^^^^^^^^^^^^^^^^^^^^^^^^^^^^^^^^^^
  File "/home/airflow/.local/lib/python3.11/site-packages/airflow/models/taskinstance.py", line 733, in _execute_callable
    return ExecutionCallableRunner(
           ^^^^^^^^^^^^^^^^^^^^^^^^
  File "/home/airflow/.local/lib/python3.11/site-packages/airflow/utils/operator_helpers.py", line 252, in run
    return self.func(*args, **kwargs)
           ^^^^^^^^^^^^^^^^^^^^^^^^^^
  File "/home/airflow/.local/lib/python3.11/site-packages/airflow/models/baseoperator.py", line 406, in wrapper
    return func(self, *args, **kwargs)
           ^^^^^^^^^^^^^^^^^^^^^^^^^^^
  File "/home/airflow/.local/lib/python3.11/site-packages/airflow/operators/bash.py", line 249, in execute
    raise AirflowException(
airflow.exceptions.AirflowException: Bash command failed. The command returned a non-zero exit code 1.
[2025-08-27T17:20:49.505+0000] {local_task_job_runner.py:266} INFO - Task exited with return code 1
[2025-08-27T17:20:49.512+0000] {taskinstance.py:3900} INFO - 0 downstream tasks scheduled from follow-on schedule check
[2025-08-27T17:20:49.512+0000] {local_task_job_runner.py:245} INFO - ::endgroup::
