[2025-08-28T00:25:04.613+0000] {local_task_job_runner.py:123} INFO - ::group::Pre task execution logs
[2025-08-28T00:25:04.616+0000] {taskinstance.py:2612} INFO - Dependencies all met for dep_context=non-requeueable deps ti=<TaskInstance: march_madness_predictions.train manual__2025-08-28T00:24:37+00:00 [queued]>
[2025-08-28T00:25:04.618+0000] {taskinstance.py:2612} INFO - Dependencies all met for dep_context=requeueable deps ti=<TaskInstance: march_madness_predictions.train manual__2025-08-28T00:24:37+00:00 [queued]>
[2025-08-28T00:25:04.618+0000] {taskinstance.py:2865} INFO - Starting attempt 1 of 2
[2025-08-28T00:25:04.623+0000] {taskinstance.py:2888} INFO - Executing <Task(BashOperator): train> on 2025-08-28 00:24:37+00:00
[2025-08-28T00:25:04.624+0000] {standard_task_runner.py:72} INFO - Started process 145 to run task
[2025-08-28T00:25:04.626+0000] {standard_task_runner.py:104} INFO - Running: ['airflow', 'tasks', 'run', 'march_madness_predictions', 'train', 'manual__2025-08-28T00:24:37+00:00', '--job-id', '4', '--raw', '--subdir', 'DAGS_FOLDER/instructions.py', '--cfg-path', '/tmp/tmpdhkp1dh7']
[2025-08-28T00:25:04.626+0000] {standard_task_runner.py:105} INFO - Job 4: Subtask train
[2025-08-28T00:25:04.638+0000] {task_command.py:467} INFO - Running <TaskInstance: march_madness_predictions.train manual__2025-08-28T00:24:37+00:00 [running]> on host 39fd42ef5bf4
[2025-08-28T00:25:04.655+0000] {taskinstance.py:3131} INFO - Exporting env vars: AIRFLOW_CTX_DAG_OWNER='airflow' AIRFLOW_CTX_DAG_ID='march_madness_predictions' AIRFLOW_CTX_TASK_ID='train' AIRFLOW_CTX_EXECUTION_DATE='2025-08-28T00:24:37+00:00' AIRFLOW_CTX_TRY_NUMBER='1' AIRFLOW_CTX_DAG_RUN_ID='manual__2025-08-28T00:24:37+00:00'
[2025-08-28T00:25:04.655+0000] {taskinstance.py:731} INFO - ::endgroup::
[2025-08-28T00:25:04.660+0000] {subprocess.py:63} INFO - Tmp dir root location: /tmp
[2025-08-28T00:25:04.661+0000] {subprocess.py:75} INFO - Running command: ['/usr/bin/bash', '-c', 'python /opt/airflow/scripts/train.py']
[2025-08-28T00:25:04.663+0000] {subprocess.py:86} INFO - Output:
[2025-08-28T00:25:05.567+0000] {subprocess.py:93} INFO - Traceback (most recent call last):
[2025-08-28T00:25:05.567+0000] {subprocess.py:93} INFO -   File "/opt/airflow/scripts/train.py", line 15, in <module>
[2025-08-28T00:25:05.568+0000] {subprocess.py:93} INFO -     X = mmkp.drop(columns=['Winner', 'Team'])
[2025-08-28T00:25:05.568+0000] {subprocess.py:93} INFO -         ^^^^^^^^^^^^^^^^^^^^^^^^^^^^^^^^^^^^^
[2025-08-28T00:25:05.568+0000] {subprocess.py:93} INFO -   File "/home/airflow/.local/lib/python3.11/site-packages/pandas/core/frame.py", line 5344, in drop
[2025-08-28T00:25:05.568+0000] {subprocess.py:93} INFO -     return super().drop(
[2025-08-28T00:25:05.568+0000] {subprocess.py:93} INFO -            ^^^^^^^^^^^^^
[2025-08-28T00:25:05.568+0000] {subprocess.py:93} INFO -   File "/home/airflow/.local/lib/python3.11/site-packages/pandas/core/generic.py", line 4711, in drop
[2025-08-28T00:25:05.568+0000] {subprocess.py:93} INFO -     obj = obj._drop_axis(labels, axis, level=level, errors=errors)
[2025-08-28T00:25:05.568+0000] {subprocess.py:93} INFO -           ^^^^^^^^^^^^^^^^^^^^^^^^^^^^^^^^^^^^^^^^^^^^^^^^^^^^^^^^
[2025-08-28T00:25:05.568+0000] {subprocess.py:93} INFO -   File "/home/airflow/.local/lib/python3.11/site-packages/pandas/core/generic.py", line 4753, in _drop_axis
[2025-08-28T00:25:05.568+0000] {subprocess.py:93} INFO -     new_axis = axis.drop(labels, errors=errors)
[2025-08-28T00:25:05.568+0000] {subprocess.py:93} INFO -                ^^^^^^^^^^^^^^^^^^^^^^^^^^^^^^^^
[2025-08-28T00:25:05.569+0000] {subprocess.py:93} INFO -   File "/home/airflow/.local/lib/python3.11/site-packages/pandas/core/indexes/base.py", line 7000, in drop
[2025-08-28T00:25:05.569+0000] {subprocess.py:93} INFO -     raise KeyError(f"{labels[mask].tolist()} not found in axis")
[2025-08-28T00:25:05.569+0000] {subprocess.py:93} INFO - KeyError: "['Team'] not found in axis"
[2025-08-28T00:25:05.627+0000] {subprocess.py:97} INFO - Command exited with return code 1
[2025-08-28T00:25:05.631+0000] {taskinstance.py:3310} ERROR - Task failed with exception
Traceback (most recent call last):
  File "/home/airflow/.local/lib/python3.11/site-packages/airflow/models/taskinstance.py", line 767, in _execute_task
    result = _execute_callable(context=context, **execute_callable_kwargs)
             ^^^^^^^^^^^^^^^^^^^^^^^^^^^^^^^^^^^^^^^^^^^^^^^^^^^^^^^^^^^^^
  File "/home/airflow/.local/lib/python3.11/site-packages/airflow/models/taskinstance.py", line 733, in _execute_callable
    return ExecutionCallableRunner(
           ^^^^^^^^^^^^^^^^^^^^^^^^
  File "/home/airflow/.local/lib/python3.11/site-packages/airflow/utils/operator_helpers.py", line 252, in run
    return self.func(*args, **kwargs)
           ^^^^^^^^^^^^^^^^^^^^^^^^^^
  File "/home/airflow/.local/lib/python3.11/site-packages/airflow/models/baseoperator.py", line 406, in wrapper
    return func(self, *args, **kwargs)
           ^^^^^^^^^^^^^^^^^^^^^^^^^^^
  File "/home/airflow/.local/lib/python3.11/site-packages/airflow/operators/bash.py", line 249, in execute
    raise AirflowException(
airflow.exceptions.AirflowException: Bash command failed. The command returned a non-zero exit code 1.
[2025-08-28T00:25:05.633+0000] {taskinstance.py:1225} INFO - Marking task as UP_FOR_RETRY. dag_id=march_madness_predictions, task_id=train, run_id=manual__2025-08-28T00:24:37+00:00, execution_date=20250828T002437, start_date=20250828T002504, end_date=20250828T002505
[2025-08-28T00:25:05.639+0000] {taskinstance.py:340} INFO - ::group::Post task execution logs
[2025-08-28T00:25:05.639+0000] {standard_task_runner.py:124} ERROR - Failed to execute job 4 for task train (Bash command failed. The command returned a non-zero exit code 1.; 145)
Traceback (most recent call last):
  File "/home/airflow/.local/lib/python3.11/site-packages/airflow/task/task_runner/standard_task_runner.py", line 117, in _start_by_fork
    ret = args.func(args, dag=self.dag)
          ^^^^^^^^^^^^^^^^^^^^^^^^^^^^^
  File "/home/airflow/.local/lib/python3.11/site-packages/airflow/cli/cli_config.py", line 49, in command
    return func(*args, **kwargs)
           ^^^^^^^^^^^^^^^^^^^^^
  File "/home/airflow/.local/lib/python3.11/site-packages/airflow/utils/cli.py", line 115, in wrapper
    return f(*args, **kwargs)
           ^^^^^^^^^^^^^^^^^^
  File "/home/airflow/.local/lib/python3.11/site-packages/airflow/cli/commands/task_command.py", line 483, in task_run
    task_return_code = _run_task_by_selected_method(args, _dag, ti)
                       ^^^^^^^^^^^^^^^^^^^^^^^^^^^^^^^^^^^^^^^^^^^^
  File "/home/airflow/.local/lib/python3.11/site-packages/airflow/cli/commands/task_command.py", line 256, in _run_task_by_selected_method
    return _run_raw_task(args, ti)
           ^^^^^^^^^^^^^^^^^^^^^^^
  File "/home/airflow/.local/lib/python3.11/site-packages/airflow/cli/commands/task_command.py", line 341, in _run_raw_task
    return ti._run_raw_task(
           ^^^^^^^^^^^^^^^^^
  File "/home/airflow/.local/lib/python3.11/site-packages/airflow/utils/session.py", line 97, in wrapper
    return func(*args, session=session, **kwargs)
           ^^^^^^^^^^^^^^^^^^^^^^^^^^^^^^^^^^^^^^
  File "/home/airflow/.local/lib/python3.11/site-packages/airflow/models/taskinstance.py", line 3004, in _run_raw_task
    return _run_raw_task(
           ^^^^^^^^^^^^^^
  File "/home/airflow/.local/lib/python3.11/site-packages/airflow/models/taskinstance.py", line 273, in _run_raw_task
    TaskInstance._execute_task_with_callbacks(
  File "/home/airflow/.local/lib/python3.11/site-packages/airflow/models/taskinstance.py", line 3158, in _execute_task_with_callbacks
    result = self._execute_task(context, task_orig)
             ^^^^^^^^^^^^^^^^^^^^^^^^^^^^^^^^^^^^^^
  File "/home/airflow/.local/lib/python3.11/site-packages/airflow/models/taskinstance.py", line 3182, in _execute_task
    return _execute_task(self, context, task_orig)
           ^^^^^^^^^^^^^^^^^^^^^^^^^^^^^^^^^^^^^^^
  File "/home/airflow/.local/lib/python3.11/site-packages/airflow/models/taskinstance.py", line 767, in _execute_task
    result = _execute_callable(context=context, **execute_callable_kwargs)
             ^^^^^^^^^^^^^^^^^^^^^^^^^^^^^^^^^^^^^^^^^^^^^^^^^^^^^^^^^^^^^
  File "/home/airflow/.local/lib/python3.11/site-packages/airflow/models/taskinstance.py", line 733, in _execute_callable
    return ExecutionCallableRunner(
           ^^^^^^^^^^^^^^^^^^^^^^^^
  File "/home/airflow/.local/lib/python3.11/site-packages/airflow/utils/operator_helpers.py", line 252, in run
    return self.func(*args, **kwargs)
           ^^^^^^^^^^^^^^^^^^^^^^^^^^
  File "/home/airflow/.local/lib/python3.11/site-packages/airflow/models/baseoperator.py", line 406, in wrapper
    return func(self, *args, **kwargs)
           ^^^^^^^^^^^^^^^^^^^^^^^^^^^
  File "/home/airflow/.local/lib/python3.11/site-packages/airflow/operators/bash.py", line 249, in execute
    raise AirflowException(
airflow.exceptions.AirflowException: Bash command failed. The command returned a non-zero exit code 1.
[2025-08-28T00:25:05.644+0000] {local_task_job_runner.py:266} INFO - Task exited with return code 1
[2025-08-28T00:25:05.650+0000] {taskinstance.py:3900} INFO - 0 downstream tasks scheduled from follow-on schedule check
[2025-08-28T00:25:05.650+0000] {local_task_job_runner.py:245} INFO - ::endgroup::
