[2025-08-28T00:36:03.099+0000] {local_task_job_runner.py:123} INFO - ::group::Pre task execution logs
[2025-08-28T00:36:03.102+0000] {taskinstance.py:2612} INFO - Dependencies all met for dep_context=non-requeueable deps ti=<TaskInstance: march_madness_predictions.predict manual__2025-08-28T00:35:42.761063+00:00 [queued]>
[2025-08-28T00:36:03.104+0000] {taskinstance.py:2612} INFO - Dependencies all met for dep_context=requeueable deps ti=<TaskInstance: march_madness_predictions.predict manual__2025-08-28T00:35:42.761063+00:00 [queued]>
[2025-08-28T00:36:03.104+0000] {taskinstance.py:2865} INFO - Starting attempt 1 of 2
[2025-08-28T00:36:03.109+0000] {taskinstance.py:2888} INFO - Executing <Task(BashOperator): predict> on 2025-08-28 00:35:42.761063+00:00
[2025-08-28T00:36:03.110+0000] {standard_task_runner.py:72} INFO - Started process 470 to run task
[2025-08-28T00:36:03.112+0000] {standard_task_runner.py:104} INFO - Running: ['airflow', 'tasks', 'run', 'march_madness_predictions', 'predict', 'manual__2025-08-28T00:35:42.761063+00:00', '--job-id', '9', '--raw', '--subdir', 'DAGS_FOLDER/instructions.py', '--cfg-path', '/tmp/tmpgfxnrs9n']
[2025-08-28T00:36:03.113+0000] {standard_task_runner.py:105} INFO - Job 9: Subtask predict
[2025-08-28T00:36:03.126+0000] {task_command.py:467} INFO - Running <TaskInstance: march_madness_predictions.predict manual__2025-08-28T00:35:42.761063+00:00 [running]> on host 9276a42765b0
[2025-08-28T00:36:03.143+0000] {taskinstance.py:3131} INFO - Exporting env vars: AIRFLOW_CTX_DAG_OWNER='airflow' AIRFLOW_CTX_DAG_ID='march_madness_predictions' AIRFLOW_CTX_TASK_ID='predict' AIRFLOW_CTX_EXECUTION_DATE='2025-08-28T00:35:42.761063+00:00' AIRFLOW_CTX_TRY_NUMBER='1' AIRFLOW_CTX_DAG_RUN_ID='manual__2025-08-28T00:35:42.761063+00:00'
[2025-08-28T00:36:03.144+0000] {taskinstance.py:731} INFO - ::endgroup::
[2025-08-28T00:36:03.149+0000] {subprocess.py:63} INFO - Tmp dir root location: /tmp
[2025-08-28T00:36:03.149+0000] {subprocess.py:75} INFO - Running command: ['/usr/bin/bash', '-c', 'python /opt/airflow/scripts/predict.py']
[2025-08-28T00:36:03.152+0000] {subprocess.py:86} INFO - Output:
[2025-08-28T00:36:03.678+0000] {subprocess.py:93} INFO - Traceback (most recent call last):
[2025-08-28T00:36:03.679+0000] {subprocess.py:93} INFO -   File "/opt/airflow/scripts/predict.py", line 23, in <module>
[2025-08-28T00:36:03.679+0000] {subprocess.py:93} INFO -     out = raw_df[test_df_cols].copy()
[2025-08-28T00:36:03.679+0000] {subprocess.py:93} INFO -           ~~~~~~^^^^^^^^^^^^^^
[2025-08-28T00:36:03.679+0000] {subprocess.py:93} INFO -   File "/home/airflow/.local/lib/python3.11/site-packages/pandas/core/frame.py", line 3899, in __getitem__
[2025-08-28T00:36:03.679+0000] {subprocess.py:93} INFO -     indexer = self.columns._get_indexer_strict(key, "columns")[1]
[2025-08-28T00:36:03.679+0000] {subprocess.py:93} INFO -               ^^^^^^^^^^^^^^^^^^^^^^^^^^^^^^^^^^^^^^^^^^^^^^^^
[2025-08-28T00:36:03.679+0000] {subprocess.py:93} INFO -   File "/home/airflow/.local/lib/python3.11/site-packages/pandas/core/indexes/base.py", line 6115, in _get_indexer_strict
[2025-08-28T00:36:03.679+0000] {subprocess.py:93} INFO -     self._raise_if_missing(keyarr, indexer, axis_name)
[2025-08-28T00:36:03.680+0000] {subprocess.py:93} INFO -   File "/home/airflow/.local/lib/python3.11/site-packages/pandas/core/indexes/base.py", line 6179, in _raise_if_missing
[2025-08-28T00:36:03.680+0000] {subprocess.py:93} INFO -     raise KeyError(f"{not_found} not in index")
[2025-08-28T00:36:03.680+0000] {subprocess.py:93} INFO - KeyError: "['Wins', 'ORtgSOS Rank', 'Losses', 'Team_Name', 'Winner'] not in index"
[2025-08-28T00:36:03.736+0000] {subprocess.py:97} INFO - Command exited with return code 1
[2025-08-28T00:36:03.739+0000] {taskinstance.py:3310} ERROR - Task failed with exception
Traceback (most recent call last):
  File "/home/airflow/.local/lib/python3.11/site-packages/airflow/models/taskinstance.py", line 767, in _execute_task
    result = _execute_callable(context=context, **execute_callable_kwargs)
             ^^^^^^^^^^^^^^^^^^^^^^^^^^^^^^^^^^^^^^^^^^^^^^^^^^^^^^^^^^^^^
  File "/home/airflow/.local/lib/python3.11/site-packages/airflow/models/taskinstance.py", line 733, in _execute_callable
    return ExecutionCallableRunner(
           ^^^^^^^^^^^^^^^^^^^^^^^^
  File "/home/airflow/.local/lib/python3.11/site-packages/airflow/utils/operator_helpers.py", line 252, in run
    return self.func(*args, **kwargs)
           ^^^^^^^^^^^^^^^^^^^^^^^^^^
  File "/home/airflow/.local/lib/python3.11/site-packages/airflow/models/baseoperator.py", line 406, in wrapper
    return func(self, *args, **kwargs)
           ^^^^^^^^^^^^^^^^^^^^^^^^^^^
  File "/home/airflow/.local/lib/python3.11/site-packages/airflow/operators/bash.py", line 249, in execute
    raise AirflowException(
airflow.exceptions.AirflowException: Bash command failed. The command returned a non-zero exit code 1.
[2025-08-28T00:36:03.741+0000] {taskinstance.py:1225} INFO - Marking task as UP_FOR_RETRY. dag_id=march_madness_predictions, task_id=predict, run_id=manual__2025-08-28T00:35:42.761063+00:00, execution_date=20250828T003542, start_date=20250828T003603, end_date=20250828T003603
[2025-08-28T00:36:03.747+0000] {taskinstance.py:340} INFO - ::group::Post task execution logs
[2025-08-28T00:36:03.747+0000] {standard_task_runner.py:124} ERROR - Failed to execute job 9 for task predict (Bash command failed. The command returned a non-zero exit code 1.; 470)
Traceback (most recent call last):
  File "/home/airflow/.local/lib/python3.11/site-packages/airflow/task/task_runner/standard_task_runner.py", line 117, in _start_by_fork
    ret = args.func(args, dag=self.dag)
          ^^^^^^^^^^^^^^^^^^^^^^^^^^^^^
  File "/home/airflow/.local/lib/python3.11/site-packages/airflow/cli/cli_config.py", line 49, in command
    return func(*args, **kwargs)
           ^^^^^^^^^^^^^^^^^^^^^
  File "/home/airflow/.local/lib/python3.11/site-packages/airflow/utils/cli.py", line 115, in wrapper
    return f(*args, **kwargs)
           ^^^^^^^^^^^^^^^^^^
  File "/home/airflow/.local/lib/python3.11/site-packages/airflow/cli/commands/task_command.py", line 483, in task_run
    task_return_code = _run_task_by_selected_method(args, _dag, ti)
                       ^^^^^^^^^^^^^^^^^^^^^^^^^^^^^^^^^^^^^^^^^^^^
  File "/home/airflow/.local/lib/python3.11/site-packages/airflow/cli/commands/task_command.py", line 256, in _run_task_by_selected_method
    return _run_raw_task(args, ti)
           ^^^^^^^^^^^^^^^^^^^^^^^
  File "/home/airflow/.local/lib/python3.11/site-packages/airflow/cli/commands/task_command.py", line 341, in _run_raw_task
    return ti._run_raw_task(
           ^^^^^^^^^^^^^^^^^
  File "/home/airflow/.local/lib/python3.11/site-packages/airflow/utils/session.py", line 97, in wrapper
    return func(*args, session=session, **kwargs)
           ^^^^^^^^^^^^^^^^^^^^^^^^^^^^^^^^^^^^^^
  File "/home/airflow/.local/lib/python3.11/site-packages/airflow/models/taskinstance.py", line 3004, in _run_raw_task
    return _run_raw_task(
           ^^^^^^^^^^^^^^
  File "/home/airflow/.local/lib/python3.11/site-packages/airflow/models/taskinstance.py", line 273, in _run_raw_task
    TaskInstance._execute_task_with_callbacks(
  File "/home/airflow/.local/lib/python3.11/site-packages/airflow/models/taskinstance.py", line 3158, in _execute_task_with_callbacks
    result = self._execute_task(context, task_orig)
             ^^^^^^^^^^^^^^^^^^^^^^^^^^^^^^^^^^^^^^
  File "/home/airflow/.local/lib/python3.11/site-packages/airflow/models/taskinstance.py", line 3182, in _execute_task
    return _execute_task(self, context, task_orig)
           ^^^^^^^^^^^^^^^^^^^^^^^^^^^^^^^^^^^^^^^
  File "/home/airflow/.local/lib/python3.11/site-packages/airflow/models/taskinstance.py", line 767, in _execute_task
    result = _execute_callable(context=context, **execute_callable_kwargs)
             ^^^^^^^^^^^^^^^^^^^^^^^^^^^^^^^^^^^^^^^^^^^^^^^^^^^^^^^^^^^^^
  File "/home/airflow/.local/lib/python3.11/site-packages/airflow/models/taskinstance.py", line 733, in _execute_callable
    return ExecutionCallableRunner(
           ^^^^^^^^^^^^^^^^^^^^^^^^
  File "/home/airflow/.local/lib/python3.11/site-packages/airflow/utils/operator_helpers.py", line 252, in run
    return self.func(*args, **kwargs)
           ^^^^^^^^^^^^^^^^^^^^^^^^^^
  File "/home/airflow/.local/lib/python3.11/site-packages/airflow/models/baseoperator.py", line 406, in wrapper
    return func(self, *args, **kwargs)
           ^^^^^^^^^^^^^^^^^^^^^^^^^^^
  File "/home/airflow/.local/lib/python3.11/site-packages/airflow/operators/bash.py", line 249, in execute
    raise AirflowException(
airflow.exceptions.AirflowException: Bash command failed. The command returned a non-zero exit code 1.
[2025-08-28T00:36:03.776+0000] {local_task_job_runner.py:266} INFO - Task exited with return code 1
[2025-08-28T00:36:03.780+0000] {taskinstance.py:3900} INFO - 0 downstream tasks scheduled from follow-on schedule check
[2025-08-28T00:36:03.780+0000] {local_task_job_runner.py:245} INFO - ::endgroup::
